Workbook
Name ANKARA: #REF!
Name DAVRANIŞ: Tablo8[DAVRANIŞ]
Name ERZURUM: #REF!
Name KARS: #REF!
Name SÜREÇ: Tablo1[SÜREÇ]
Name TEŞEKKÜR: Tablo9[TEŞEKKÜR]
Name ÜRÜN: Tablo2[ÜRÜN]

Sheet Data
A1: Geliş Kanalı | B1: Yapılacak İş No | C1: Telefon No | D1: Şirket | E1: Skıll | F1: Agent ID | G1: MT İsim Soyisim | H1: Takım Lideri | I1: Lokasyon | J1: Ünvan | K1: Çağrının Konusu | L1: Şikayet Ana Nedeni | M1: Şikayet Alt Nedeni | N1: Yapılacak İş Kayıt Tarihi | O1: Yapılacak İş Kapatma Tarihi | P1: Yapılacak İş Sonucu | Q1: Fraud (Tele Satış) | R1: Kalite Yetkilisi | S1: Kalite Değerlendirmesi | T1: Mail İletildi Mi? | U1: Çağrı Skoru | V1: Şikayet Oluşturma Ayı | W1: Kaydı Oluşturan MT Agent ID | X1: Kaydı Oluşturan MT İsim Soyisim | Y1: Kaydı Oluşturan MT Takım Lideri | Z1: Kayıt Oluşturan MT Hatalı Mı? | AA1: Hata Sebebi Olan Durum Nedir? | AB1: Çağrının Konusu | AC1: Şikayet Ana Nedeni | AD1: Şikayet Alt Nedeni | AE1: Şikayete Konu Olan Kaç Çağrı Dinlemesi Yapıldı | AF1: 1. Çağrı Süresi | AG1: 2. Çağrı Süresi
A2: ÇAĞRI MERKEZİ | B2: * 51845849181625 | C2: 5514232692 | D2: BEDAŞ | E2: =IFERROR(VLOOKUP(D2,Tanımlar!C:D,2,0),"- - -") -> DAĞITIM | F2: 500179 | G2: =IFERROR(VLOOKUP(F2,'Personel Bilgi'!A:B,2,0),"- - - ") -> HANIFE UZUN | H2: =IFERROR(VLOOKUP(F2,'Personel Bilgi'!A:D,3,0),"- - -") -> SAMET KOCABEYOGLU | I2: =IFERROR(VLOOKUP(F2,'Personel Bilgi'!A:D,4,0),"- - -") -> ERZURUM | J2: =IFERROR(VLOOKUP(F2,'Personel Bilgi'!A:E,5,0),"- - -") -> MÜŞTERİ TEMSİLCİSİ | K2: ARIZA | L2: ÜRÜN | M2: HATALI / EKSİK KESİNTİ SÜREÇLERİ BİLGİLENDİRMESİ | N2: 45992 | O2: 45992 | P2: GEÇERSİZ ŞİKAYET | Q2: - | R2: HALİDE PALAVAR | S2: YAPILMADI | T2: HAYIR | U2: - | V2: ARALIK | W2: 500081 | X2: =IFERROR(VLOOKUP(W2,'Personel Bilgi'!A:B,2,0),"---") -> BEYZA YAREN TUNCAY | Y2: =IFERROR(VLOOKUP(W2,'Personel Bilgi'!A:C,3,0),"---") -> SALTUK BUGRAHAN TAYMUS | Z2: HAYIR | AA2: HATASIZ ÇAĞRI | AB2: ARIZA | AC2: ÜRÜN | AD2: HATALI / EKSİK KESİNTİ SÜREÇLERİ BİLGİLENDİRMESİ
A3: ÇAĞRI MERKEZİ | B3: *74435738826854 | C3: 5076271698 | D3: ÇEDAŞ | E3: =IFERROR(VLOOKUP(D3,Tanımlar!C:D,2,0),"- - -") -> DAĞITIM | F3: 111220 | G3: =IFERROR(VLOOKUP(F3,'Personel Bilgi'!A:B,2,0),"- - - ") -> MAHIZER BUKET AKBABA | H3: =IFERROR(VLOOKUP(F3,'Personel Bilgi'!A:D,3,0),"- - -") -> SAFAK TOPTAS | I3: =IFERROR(VLOOKUP(F3,'Personel Bilgi'!A:D,4,0),"- - -") -> KARS | J3: =IFERROR(VLOOKUP(F3,'Personel Bilgi'!A:E,5,0),"- - -") -> MÜŞTERİ TEMSİLCİSİ | K3: ARIZA | L3: DAVRANIŞ | M3: TAVIR, TARZ YAPMAK, SES YÜKSELTMEK VB. | N3: 45994 | O3: 45994 | P3: GEÇERSİZ ŞİKAYET | Q3: - | R3: HALİDE PALAVAR | S3: YAPILMADI | T3: HAYIR | U3: - | V3: ARALIK | W3: 500081 | X3: =IFERROR(VLOOKUP(W3,'Personel Bilgi'!A:B,2,0),"---") -> BEYZA YAREN TUNCAY | Y3: =IFERROR(VLOOKUP(W3,'Personel Bilgi'!A:C,3,0),"---") -> SALTUK BUGRAHAN TAYMUS | Z3: HAYIR | AA3: HATASIZ ÇAĞRI | AB3: ARIZA | AC3: DAVRANIŞ | AD3: TAVIR, TARZ YAPMAK, SES YÜKSELTMEK VB.
A4: ÇAĞRI MERKEZİ | B4: *16193879313370 | C4: 5383176934 | D4: BEDAŞ | E4: =IFERROR(VLOOKUP(D4,Tanımlar!C:D,2,0),"- - -") -> DAĞITIM | F4: 500141 | G4: =IFERROR(VLOOKUP(F4,'Personel Bilgi'!A:B,2,0),"- - - ") -> ZIHNI AKPINAR | H4: =IFERROR(VLOOKUP(F4,'Personel Bilgi'!A:D,3,0),"- - -") -> SAMET KOCABEYOGLU | I4: =IFERROR(VLOOKUP(F4,'Personel Bilgi'!A:D,4,0),"- - -") -> ERZURUM | J4: =IFERROR(VLOOKUP(F4,'Personel Bilgi'!A:E,5,0),"- - -") -> MÜŞTERİ TEMSİLCİSİ | K4: ARIZA | L4: SÜREÇ | M4: HATALI MÜHİM/MOD/ÇAĞRI MERKEZİ VB. YÖNLENDİRME | N4: 45993 | O4: 45994 | P4: SÖZLÜ UYARI YAPILDI | Q4: - | R4: HALİDE PALAVAR | S4: YAPILDI | T4: EVET | U4: 0 | V4: ARALIK | W4: 500153 | X4: =IFERROR(VLOOKUP(W4,'Personel Bilgi'!A:B,2,0),"---") -> ESRA YILMAZ | Y4: =IFERROR(VLOOKUP(W4,'Personel Bilgi'!A:C,3,0),"---") -> KURSAD TERCANLI | Z4: HAYIR | AA4: HATASIZ ÇAĞRI | AB4: ARIZA | AC4: SÜREÇ | AD4: HATALI MÜHİM/MOD/ÇAĞRI MERKEZİ VB. YÖNLENDİRME
A5: ÇAĞRI MERKEZİ | B5: *23115844499930 | C5: 5536499902 | D5: AEDAŞ | E5: =IFERROR(VLOOKUP(D5,Tanımlar!C:D,2,0),"- - -") -> DAĞITIM | F5: 500170 | G5: =IFERROR(VLOOKUP(F5,'Personel Bilgi'!A:B,2,0),"- - - ") -> BURAK KAYA | H5: =IFERROR(VLOOKUP(F5,'Personel Bilgi'!A:D,3,0),"- - -") -> ERDOGAN DURUK | I5: =IFERROR(VLOOKUP(F5,'Personel Bilgi'!A:D,4,0),"- - -") -> ERZURUM | J5: =IFERROR(VLOOKUP(F5,'Personel Bilgi'!A:E,5,0),"- - -") -> MÜŞTERİ TEMSİLCİSİ | K5: AYDINLATMA | L5: ÜRÜN | M5: HATALI / EKSİK AYDINLATMA BİLGİLENDİRMESİ | N5: 45993 | O5: 45994 | P5: GEÇERSİZ ŞİKAYET | Q5: - | R5: RUKİYE DEMİRKALE | S5: YAPILDI | T5: EVET | U5: 0 | V5: ARALIK | W5: 500155 | X5: =IFERROR(VLOOKUP(W5,'Personel Bilgi'!A:B,2,0),"---") -> FATMA NUR EZGIN | Y5: =IFERROR(VLOOKUP(W5,'Personel Bilgi'!A:C,3,0),"---") -> KURSAD TERCANLI | Z5: EVET | AA5: HATALI / EKSİK BİLGİ VERME | AB5: AYDINLATMA | AC5: ÜRÜN | AD5: HATALI / EKSİK AYDINLATMA BİLGİLENDİRMESİ
A6: ÇAĞRI MERKEZİ | B6: * 61233088579921 | C6: 5333533859 | D6: BEPSAŞ | E6: =IFERROR(VLOOKUP(D6,Tanımlar!C:D,2,0),"- - -") -> PERAKENDE | F6: 600528 | G6: =IFERROR(VLOOKUP(F6,'Personel Bilgi'!A:B,2,0),"- - - ") -> SERAP COSKUNARSLAN | H6: =IFERROR(VLOOKUP(F6,'Personel Bilgi'!A:D,3,0),"- - -") -> GORKEM SERT | I6: =IFERROR(VLOOKUP(F6,'Personel Bilgi'!A:D,4,0),"- - -") -> ANKARA | J6: =IFERROR(VLOOKUP(F6,'Personel Bilgi'!A:E,5,0),"- - -") -> MÜŞTERİ TEMSİLCİSİ | K6: FATURA İŞLEMLERİ | L6: SÜREÇ | M6: HATALI MÜHİM/MOD/ÇAĞRI MERKEZİ VB. YÖNLENDİRME | N6: 45993 | O6: 46006 | P6: GEÇERSİZ ŞİKAYET | Q6: - | R6: HALİDE PALAVAR | S6: YAPILDI | T6: HAYIR | U6: 100 | V6: ARALIK | W6: 111108 | X6: =IFERROR(VLOOKUP(W6,'Personel Bilgi'!A:B,2,0),"---") -> BERKAN COSKUNOZ | Y6: =IFERROR(VLOOKUP(W6,'Personel Bilgi'!A:C,3,0),"---") -> KURTHAN FERDI CIHANTIMUR | Z6: HAYIR | AA6: HATASIZ ÇAĞRI | AB6: FATURA İŞLEMLERİ | AC6: SÜREÇ | AD6: HATALI MÜHİM/MOD/ÇAĞRI MERKEZİ VB. YÖNLENDİRME
A7: ÇAĞRI MERKEZİ | B7: * 91625930669158 | C7: 5317348507 | D7: AEPSAŞ | E7: =IFERROR(VLOOKUP(D7,Tanımlar!C:D,2,0),"- - -") -> PERAKENDE | F7: 600558 | G7: =IFERROR(VLOOKUP(F7,'Personel Bilgi'!A:B,2,0),"- - - ") -> MELIKE TOPSOY | H7: =IFERROR(VLOOKUP(F7,'Personel Bilgi'!A:D,3,0),"- - -") -> BUSRA OLCULMUS | I7: =IFERROR(VLOOKUP(F7,'Personel Bilgi'!A:D,4,0),"- - -") -> ANKARA | J7: =IFERROR(VLOOKUP(F7,'Personel Bilgi'!A:E,5,0),"- - -") -> MÜŞTERİ TEMSİLCİSİ | K7: FATURA İŞLEMLERİ | L7: ÜRÜN | M7: HATALI / EKSİK BORÇ BİLGİLENDİRMESİ | N7: 45993 | O7: 45995 | P7: GEÇERSİZ ŞİKAYET | Q7: - | R7: HALİDE PALAVAR | S7: YAPILDI | T7: HAYIR | U7: 100 | V7: ARALIK | W7: 110707 | X7: =IFERROR(VLOOKUP(W7,'Personel Bilgi'!A:B,2,0),"---") -> MELISA YIGIT | Y7: =IFERROR(VLOOKUP(W7,'Personel Bilgi'!A:C,3,0),"---") -> MUHAMMET AKSU | Z7: EVET | AA7: HATALI / EKSİK BİLGİ VERME | AB7: FATURA İŞLEMLERİ | AC7: ÜRÜN | AD7: HATALI / EKSİK BORÇ BİLGİLENDİRMESİ
A8: ÇAĞRI MERKEZİ | B8: *73941030689760 | C8: 5339501821 | D8: BEDAŞ | E8: =IFERROR(VLOOKUP(D8,Tanımlar!C:D,2,0),"- - -") -> DAĞITIM | F8: 600032 | G8: =IFERROR(VLOOKUP(F8,'Personel Bilgi'!A:B,2,0),"- - - ") -> ASYA DAG | H8: =IFERROR(VLOOKUP(F8,'Personel Bilgi'!A:D,3,0),"- - -") -> ASYA DAG | I8: =IFERROR(VLOOKUP(F8,'Personel Bilgi'!A:D,4,0),"- - -") -> ANKARA | J8: =IFERROR(VLOOKUP(F8,'Personel Bilgi'!A:E,5,0),"- - -") -> TAKIM LİDERİ | K8: ARIZA | L8: SÜREÇ | M8: MÜŞTERİ TALEBİNE YARDIMCI OLMAMASI | N8: 45994 | O8: 45996 | P8: GEÇERSİZ ŞİKAYET | Q8: - | R8: HALİDE PALAVAR | S8: YAPILMADI | T8: HAYIR | U8: - | V8: ARALIK | W8: 110707 | X8: =IFERROR(VLOOKUP(W8,'Personel Bilgi'!A:B,2,0),"---") -> MELISA YIGIT | Y8: =IFERROR(VLOOKUP(W8,'Personel Bilgi'!A:C,3,0),"---") -> MUHAMMET AKSU | Z8: =IFERROR(VLOOKUP(X8,'Personel Bilgi'!B:D,3,0),"---") -> KARS | AA8: =IFERROR(VLOOKUP(Y8,'Personel Bilgi'!C:E,3,0),"---") -> MÜŞTERİ TEMSİLCİSİ | AB8: ARIZA | AC8: SÜREÇ | AD8: MÜŞTERİ TALEBİNE YARDIMCI OLMAMASI
A9: ÇAĞRI MERKEZİ | B9: *50695329682690 - 53110455139033 | C9: 5060215966 | D9: AEPSAŞ | E9: =IFERROR(VLOOKUP(D9,Tanımlar!C:D,2,0),"- - -") -> PERAKENDE | F9: 110917 | G9: =IFERROR(VLOOKUP(F9,'Personel Bilgi'!A:B,2,0),"- - - ") -> BERAT ACAY | H9: =IFERROR(VLOOKUP(F9,'Personel Bilgi'!A:D,3,0),"- - -") -> YAPRAK KARAKOC | I9: =IFERROR(VLOOKUP(F9,'Personel Bilgi'!A:D,4,0),"- - -") -> KARS | J9: =IFERROR(VLOOKUP(F9,'Personel Bilgi'!A:E,5,0),"- - -") -> MÜŞTERİ TEMSİLCİSİ | K9: FATURA İŞLEMLERİ | L9: DAVRANIŞ | M9: TAVIR, TARZ YAPMAK, SES YÜKSELTMEK VB. | N9: 45994 | O9: 45996 | P9: YAZILI UYARI YAPILDI | Q9: - | R9: HALİDE PALAVAR | S9: YAPILDI | T9: EVET | U9: 0 | V9: ARALIK | W9: 110707 | X9: =IFERROR(VLOOKUP(W9,'Personel Bilgi'!A:B,2,0),"---") -> MELISA YIGIT | Y9: =IFERROR(VLOOKUP(W9,'Personel Bilgi'!A:C,3,0),"---") -> MUHAMMET AKSU | Z9: =IFERROR(VLOOKUP(X9,'Personel Bilgi'!B:D,3,0),"---") -> KARS | AA9: =IFERROR(VLOOKUP(Y9,'Personel Bilgi'!C:E,3,0),"---") -> MÜŞTERİ TEMSİLCİSİ | AB9: FATURA İŞLEMLERİ | AC9: DAVRANIŞ | AD9: TAVIR, TARZ YAPMAK, SES YÜKSELTMEK VB.
A10: ÇAĞRI MERKEZİ | B10: * 41077155367913 | C10: 5326705837 | D10: BEPSAŞ | E10: =IFERROR(VLOOKUP(D10,Tanımlar!C:D,2,0),"- - -") -> PERAKENDE | F10: 111131 | G10: =IFERROR(VLOOKUP(F10,'Personel Bilgi'!A:B,2,0),"- - - ") -> ASENA BANU SONKURT | H10: =IFERROR(VLOOKUP(F10,'Personel Bilgi'!A:D,3,0),"- - -") -> YAPRAK KARAKOC | I10: =IFERROR(VLOOKUP(F10,'Personel Bilgi'!A:D,4,0),"- - -") -> KARS | J10: =IFERROR(VLOOKUP(F10,'Personel Bilgi'!A:E,5,0),"- - -") -> MÜŞTERİ TEMSİLCİSİ | K10: MÜŞTERİ İŞLEMLERİ | L10: DAVRANIŞ | M10: STANDARDA UYGUN OLMAYAN ÇAĞRI SONLANDIRMA | N10: 45994 | O10: 45996 | P10: GEÇERSİZ ŞİKAYET | Q10: - | R10: HALİDE PALAVAR | S10: YAPILDI | T10: HAYIR | U10: 55 | V10: ARALIK | W10: 210162 | X10: =IFERROR(VLOOKUP(W10,'Personel Bilgi'!A:B,2,0),"---") -> FUNDA YAKISIR | Y10: =IFERROR(VLOOKUP(W10,'Personel Bilgi'!A:C,3,0),"---") -> YAPRAK KARAKOC | Z10: HAYIR | AA10: HATASIZ ÇAĞRI | AB10: MÜŞTERİ İŞLEMLERİ | AC10: DAVRANIŞ | AD10: STANDARDA UYGUN OLMAYAN ÇAĞRI SONLANDIRMA
A11: ÇAĞRI MERKEZİ | B11: * 41077155367913 | C11: 5326705837 | D11: BEPSAŞ | E11: =IFERROR(VLOOKUP(D11,Tanımlar!C:D,2,0),"- - -") -> PERAKENDE | F11: 111098 | G11: =IFERROR(VLOOKUP(F11,'Personel Bilgi'!A:B,2,0),"- - - ") -> YETER DEMIRCI | H11: =IFERROR(VLOOKUP(F11,'Personel Bilgi'!A:D,3,0),"- - -") -> CEYHAN AYRIC | I11: =IFERROR(VLOOKUP(F11,'Personel Bilgi'!A:D,4,0),"- - -") -> KARS | J11: =IFERROR(VLOOKUP(F11,'Personel Bilgi'!A:E,5,0),"- - -") -> MÜŞTERİ TEMSİLCİSİ | K11: MÜŞTERİ İŞLEMLERİ | L11: DAVRANIŞ | M11: MÜŞTERİNİN YÜZÜNE TELEFON KAPATMA | N11: 45994 | O11: 45996 | P11: GEÇERSİZ ŞİKAYET | Q11: - | R11: HALİDE PALAVAR | S11: YAPILDI | T11: EVET | U11: 0 | V11: ARALIK | W11: 210162 | X11: =IFERROR(VLOOKUP(W11,'Personel Bilgi'!A:B,2,0),"---") -> FUNDA YAKISIR | Y11: =IFERROR(VLOOKUP(W11,'Personel Bilgi'!A:C,3,0),"---") -> YAPRAK KARAKOC | Z11: HAYIR | AA11: HATASIZ ÇAĞRI | AB11: MÜŞTERİ İŞLEMLERİ | AC11: DAVRANIŞ | AD11: MÜŞTERİNİN YÜZÜNE TELEFON KAPATMA
A12: ÇAĞRI MERKEZİ | B12: *50785633953374 | C12: 5449182443 | D12: BEDAŞ | E12: =IFERROR(VLOOKUP(D12,Tanımlar!C:D,2,0),"- - -") -> DAĞITIM | F12: 500164 | G12: =IFERROR(VLOOKUP(F12,'Personel Bilgi'!A:B,2,0),"- - - ") -> MUHAMMET TALHA BERKAY TERCANLI | H12: =IFERROR(VLOOKUP(F12,'Personel Bilgi'!A:D,3,0),"- - -") -> KURSAD TERCANLI | I12: =IFERROR(VLOOKUP(F12,'Personel Bilgi'!A:D,4,0),"- - -") -> ERZURUM | J12: =IFERROR(VLOOKUP(F12,'Personel Bilgi'!A:E,5,0),"- - -") -> MÜŞTERİ TEMSİLCİSİ | K12: GENEL TALEPLER | L12: DAVRANIŞ | M12: MÜŞTERİNİN İSTEĞİ DIŞINDA ÇAĞRININ SONLANDIRILMASI | N12: 45992 | O12: 45993 | P12: GEÇERSİZ ŞİKAYET | Q12: - | R12: ŞEYMANUR ÇEVİK | S12: YAPILMADI | T12: HAYIR | U12: - | V12: ARALIK | W12: 111192 | X12: =IFERROR(VLOOKUP(W12,'Personel Bilgi'!A:B,2,0),"---") -> RABIA TEMUR | Y12: =IFERROR(VLOOKUP(W12,'Personel Bilgi'!A:C,3,0),"---") -> MUSTAFA OZAYAG | Z12: HAYIR | AA12: HATASIZ ÇAĞRI | AB12: GENEL TALEPLER | AC12: DAVRANIŞ | AD12: MÜŞTERİNİN İSTEĞİ DIŞINDA ÇAĞRININ SONLANDIRILMASI
A13: ÇAĞRI MERKEZİ | B13: *64468646961494 | C13: 5301327734 | D13: BEDAŞ | E13: =IFERROR(VLOOKUP(D13,Tanımlar!C:D,2,0),"- - -") -> DAĞITIM | F13: 500025 | G13: METEHAN EMRE SIRMALI | H13: METEHAN EMRE SIRMALI | I13: ERZURUM | J13: TAKIM LIDERI | K13: ARIZA | L13: SÜREÇ | M13: YETKİLİYE AKTARMAMA | N13: 45993 | O13: 45993 | P13: GEÇERSİZ ŞİKAYET | Q13: - | R13: ŞEYMANUR ÇEVİK | S13: YAPILMADI | T13: HAYIR | U13: - | V13: ARALIK | W13: 500107 | X13: =IFERROR(VLOOKUP(W13,'Personel Bilgi'!A:B,2,0),"---") -> MERVENUR CELIK | Y13: =IFERROR(VLOOKUP(W13,'Personel Bilgi'!A:C,3,0),"---") -> METEHAN EMRE SIRMALI | Z13: HAYIR | AA13: HATASIZ ÇAĞRI | AB13: ARIZA | AC13: SÜREÇ | AD13: YETKİLİYE AKTARMAMA
A14: ÇAĞRI MERKEZİ | B14: *52922832646944 | C14: 5056692737 | D14: BEDAŞ | E14: =IFERROR(VLOOKUP(D14,Tanımlar!C:D,2,0),"- - -") -> DAĞITIM | F14: 111049 | G14: =IFERROR(VLOOKUP(F14,'Personel Bilgi'!A:B,2,0),"- - - ") -> BUSRA YILDIRIM | H14: =IFERROR(VLOOKUP(F14,'Personel Bilgi'!A:D,3,0),"- - -") -> YAREN OZAYAG | I14: =IFERROR(VLOOKUP(F14,'Personel Bilgi'!A:D,4,0),"- - -") -> KARS | J14: =IFERROR(VLOOKUP(F14,'Personel Bilgi'!A:E,5,0),"- - -") -> MÜŞTERİ TEMSİLCİSİ | K14: AYDINLATMA | L14: ÜRÜN | M14: HATALI / EKSİK AYDINLATMA BİLGİLENDİRMESİ | N14: 45993 | O14: 45993 | P14: GEÇERSİZ ŞİKAYET | Q14: - | R14: ŞEYMANUR ÇEVİK | S14: YAPILDI | T14: HAYIR | U14: 100 | V14: ARALIK | W14: 500083 | X14: =IFERROR(VLOOKUP(W14,'Personel Bilgi'!A:B,2,0),"---") -> SEDANUR ARSLAN | Y14: =IFERROR(VLOOKUP(W14,'Personel Bilgi'!A:C,3,0),"---") -> SALTUK BUGRAHAN TAYMUS | Z14: HAYIR | AA14: HATASIZ ÇAĞRI | AB14: AYDINLATMA | AC14: ÜRÜN | AD14: HATALI / EKSİK AYDINLATMA BİLGİLENDİRMESİ
A15: ÇAĞRI MERKEZİ | B15: *08792139248286 | C15: 5010881907 | D15: BEDAŞ | E15: =IFERROR(VLOOKUP(D15,Tanımlar!C:D,2,0),"- - -") -> DAĞITIM | F15: 600189 | G15: MEHMET ALI SAVAN | H15: MEHMET ALI SAVAN | I15: =IFERROR(VLOOKUP(F15,'Personel Bilgi'!A:D,4,0),"- - -") -> ERZURUM | J15: TAKIM LIDERI | K15: MÜŞTERİ HİZMETLERİ | L15: SÜREÇ | M15: YETKİLİYE AKTARMAMA | N15: 45993 | O15: 45993 | P15: GEÇERSİZ ŞİKAYET | Q15: - | R15: ŞEYMANUR ÇEVİK | S15: YAPILMADI | T15: HAYIR | U15: - | V15: ARALIK | W15: 500049 | X15: =IFERROR(VLOOKUP(W15,'Personel Bilgi'!A:B,2,0),"---") -> FERHAT ATICI | Y15: =IFERROR(VLOOKUP(W15,'Personel Bilgi'!A:C,3,0),"---") -> MEHMET ALI SAVAN | Z15: HAYIR | AA15: HATASIZ ÇAĞRI | AB15: MÜŞTERİ HİZMETLERİ | AC15: SÜREÇ | AD15: YETKİLİYE AKTARMAMA
A16: ÇAĞRI MERKEZİ | B16: *41276545567359 | C16: 5010881907 | D16: BEDAŞ | E16: =IFERROR(VLOOKUP(D16,Tanımlar!C:D,2,0),"- - -") -> DAĞITIM | F16: 500065 | G16: =IFERROR(VLOOKUP(F16,'Personel Bilgi'!A:B,2,0),"- - - ") -> BATUHAN GULER | H16: =IFERROR(VLOOKUP(F16,'Personel Bilgi'!A:D,3,0),"- - -") -> SALTUK BUGRAHAN TAYMUS | I16: =IFERROR(VLOOKUP(F16,'Personel Bilgi'!A:D,4,0),"- - -") -> ERZURUM | J16: =IFERROR(VLOOKUP(F16,'Personel Bilgi'!A:E,5,0),"- - -") -> MÜŞTERİ TEMSİLCİSİ | K16: MÜŞTERİ HİZMETLERİ | L16: SÜREÇ | M16: YETKİLİYE AKTARMAMA | N16: 45993 | O16: 45993 | P16: SÖZLÜ UYARI YAPILDI | Q16: - | R16: ŞEYMANUR ÇEVİK | S16: YAPILDI | T16: EVET | U16: 0 | V16: ARALIK | W16: 500049 | X16: =IFERROR(VLOOKUP(W16,'Personel Bilgi'!A:B,2,0),"---") -> FERHAT ATICI | Y16: =IFERROR(VLOOKUP(W16,'Personel Bilgi'!A:C,3,0),"---") -> MEHMET ALI SAVAN | Z16: HAYIR | AA16: HATASIZ ÇAĞRI | AB16: MÜŞTERİ HİZMETLERİ | AC16: SÜREÇ | AD16: YETKİLİYE AKTARMAMA
A17: ÇAĞRI MERKEZİ | B17: * 41077155367913 | C17: 5326705837 | D17: BEPSAŞ | E17: =IFERROR(VLOOKUP(D17,Tanımlar!C:D,2,0),"- - -") -> PERAKENDE | F17: 600657 | G17: =IFERROR(VLOOKUP(F17,'Personel Bilgi'!A:B,2,0),"- - - ") -> SEHER ERCAN | H17: =IFERROR(VLOOKUP(F17,'Personel Bilgi'!A:D,3,0),"- - -") -> FERHAT DEMIR | I17: =IFERROR(VLOOKUP(F17,'Personel Bilgi'!A:D,4,0),"- - -") -> ANKARA | J17: =IFERROR(VLOOKUP(F17,'Personel Bilgi'!A:E,5,0),"- - -") -> MÜŞTERİ TEMSİLCİSİ | K17: MÜŞTERİ HİZMETLERİ | L17: SÜREÇ | M17: MÜŞTERİ TALEBİNE YARDIMCI OLMAMASI | N17: 45994 | O17: 45999 | P17: GEÇERSİZ ŞİKAYET | Q17: - | R17: HALİDE PALAVAR | S17: YAPILDI | T17: HAYIR | U17: 90 | V17: ARALIK | W17: 210162 | X17: =IFERROR(VLOOKUP(W17,'Personel Bilgi'!A:B,2,0),"---") -> FUNDA YAKISIR | Y17: =IFERROR(VLOOKUP(W17,'Personel Bilgi'!A:C,3,0),"---") -> YAPRAK KARAKOC | Z17: HAYIR | AA17: HATASIZ ÇAĞRI | AB17: MÜŞTERİ HİZMETLERİ | AC17: SÜREÇ | AD17: MÜŞTERİ TALEBİNE YARDIMCI OLMAMASI
A18: ÇAĞRI MERKEZİ | B18: *82256775727712 | C18: 5300869157 | D18: BEDAŞ | E18: =IFERROR(VLOOKUP(D18,Tanımlar!C:D,2,0),"- - -") -> DAĞITIM | F18: 111197 | G18: =IFERROR(VLOOKUP(F18,'Personel Bilgi'!A:B,2,0),"- - - ") -> SONGUL YAGCI | H18: =IFERROR(VLOOKUP(F18,'Personel Bilgi'!A:D,3,0),"- - -") -> SEDA SEBU | I18: =IFERROR(VLOOKUP(F18,'Personel Bilgi'!A:D,4,0),"- - -") -> KARS | J18: =IFERROR(VLOOKUP(F18,'Personel Bilgi'!A:E,5,0),"- - -") -> MÜŞTERİ TEMSİLCİSİ | K18: ARIZA | L18: ÜRÜN | M18: HATALI / EKSİK KESİNTİ SÜREÇLERİ BİLGİLENDİRMESİ | N18: 45996 | O18: 45999 | P18: GEÇERSİZ ŞİKAYET | Q18: - | R18: HALİDE PALAVAR | S18: YAPILDI | T18: HAYIR | V18: ARALIK | W18: 500167 | X18: =IFERROR(VLOOKUP(W18,'Personel Bilgi'!A:B,2,0),"---") -> NEVA OZMEN | Y18: =IFERROR(VLOOKUP(W18,'Personel Bilgi'!A:C,3,0),"---") -> KURSAD TERCANLI | Z18: HAYIR | AA18: HATASIZ ÇAĞRI | AB18: ARIZA | AC18: ÜRÜN | AD18: HATALI / EKSİK KESİNTİ SÜREÇLERİ BİLGİLENDİRMESİ
A19: ÇAĞRI MERKEZİ | B19: *82256775727712 | C19: 5300869157 | D19: BEDAŞ | E19: =IFERROR(VLOOKUP(D19,Tanımlar!C:D,2,0),"- - -") -> DAĞITIM | F19: 111199 | G19: =IFERROR(VLOOKUP(F19,'Personel Bilgi'!A:B,2,0),"- - - ") -> UMMUGULSUM BEKI | H19: =IFERROR(VLOOKUP(F19,'Personel Bilgi'!A:D,3,0),"- - -") -> MUHAMMET AKSU | I19: =IFERROR(VLOOKUP(F19,'Personel Bilgi'!A:D,4,0),"- - -") -> KARS | J19: =IFERROR(VLOOKUP(F19,'Personel Bilgi'!A:E,5,0),"- - -") -> MÜŞTERİ TEMSİLCİSİ | K19: ARIZA | L19: ÜRÜN | M19: HATALI / EKSİK KESİNTİ SÜREÇLERİ BİLGİLENDİRMESİ | N19: 45996 | O19: 45999 | P19: SÖZLÜ UYARI YAPILDI | Q19: - | R19: HALİDE PALAVAR | S19: YAPILDI | T19: EVET | U19: 0 | V19: ARALIK | W19: 500167 | X19: =IFERROR(VLOOKUP(W19,'Personel Bilgi'!A:B,2,0),"---") -> NEVA OZMEN | Y19: =IFERROR(VLOOKUP(W19,'Personel Bilgi'!A:C,3,0),"---") -> KURSAD TERCANLI | Z19: HAYIR | AA19: HATASIZ ÇAĞRI | AB19: ARIZA | AC19: ÜRÜN | AD19: HATALI / EKSİK KESİNTİ SÜREÇLERİ BİLGİLENDİRMESİ
A20: ÇAĞRI MERKEZİ | B20: * 06692573271774 | C20: 5530630004 | D20: BEDAŞ | E20: =IFERROR(VLOOKUP(D20,Tanımlar!C:D,2,0),"- - -") -> DAĞITIM | F20: 600189 | G20: =IFERROR(VLOOKUP(F20,'Personel Bilgi'!A:B,2,0),"- - - ") -> MEHMET ALI SAVAN | H20: =IFERROR(VLOOKUP(F20,'Personel Bilgi'!A:D,3,0),"- - -") -> MEHMET ALI SAVAN | I20: =IFERROR(VLOOKUP(F20,'Personel Bilgi'!A:D,4,0),"- - -") -> ERZURUM | J20: =IFERROR(VLOOKUP(F20,'Personel Bilgi'!A:E,5,0),"- - -") -> TAKIM LİDERİ | K20: ARIZA | L20: SÜREÇ | M20: YETKİLİYE AKTARMAMA | N20: 45998 | O20: 45999 | P20: GEÇERSİZ ŞİKAYET | Q20: - | R20: HALİDE PALAVAR | S20: YAPILMADI | T20: HAYIR | U20: - | V20: ARALIK | W20: 110471 | X20: =IFERROR(VLOOKUP(W20,'Personel Bilgi'!A:B,2,0),"---") -> TUGBA DEMIR | Y20: =IFERROR(VLOOKUP(W20,'Personel Bilgi'!A:C,3,0),"---") -> ERCUMENT GUNESSU | Z20: HAYIR | AA20: HATASIZ ÇAĞRI | AB20: ARIZA | AC20: SÜREÇ | AD20: YETKİLİYE AKTARMAMA
A21: ÇAĞRI MERKEZİ | B21: * 29588671274849 | C21: 5437876246 | D21: BEDAŞ | E21: =IFERROR(VLOOKUP(D21,Tanımlar!C:D,2,0),"- - -") -> DAĞITIM | F21: 500132 | G21: =IFERROR(VLOOKUP(F21,'Personel Bilgi'!A:B,2,0),"- - - ") -> SONGUL BEKCI | H21: =IFERROR(VLOOKUP(F21,'Personel Bilgi'!A:D,3,0),"- - -") -> TURGUT AKDAG | I21: =IFERROR(VLOOKUP(F21,'Personel Bilgi'!A:D,4,0),"- - -") -> ERZURUM | J21: =IFERROR(VLOOKUP(F21,'Personel Bilgi'!A:E,5,0),"- - -") -> MÜŞTERİ TEMSİLCİSİ | K21: GENEL TALEPLER | L21: DAVRANIŞ | M21: MÜŞTERİNİN YÜZÜNE TELEFON KAPATMA | N21: 45997 | O21: 45999 | P21: GEÇERSİZ ŞİKAYET | Q21: - | R21: HALİDE PALAVAR | S21: YAPILMADI | T21: HAYIR | U21: - | V21: ARALIK | W21: 500131 | X21: =IFERROR(VLOOKUP(W21,'Personel Bilgi'!A:B,2,0),"---") -> SIBEL ATES | Y21: =IFERROR(VLOOKUP(W21,'Personel Bilgi'!A:C,3,0),"---") -> TURGUT AKDAG | Z21: HAYIR | AA21: HATASIZ ÇAĞRI | AB21: GENEL TALEPLER | AC21: DAVRANIŞ | AD21: MÜŞTERİNİN YÜZÜNE TELEFON KAPATMA
A22: ÇAĞRI MERKEZİ | B22: * 29588671274849 | C22: 5437876246 | D22: BEDAŞ | E22: =IFERROR(VLOOKUP(D22,Tanımlar!C:D,2,0),"- - -") -> DAĞITIM | F22: 500145 | G22: =IFERROR(VLOOKUP(F22,'Personel Bilgi'!A:B,2,0),"- - - ") -> BELMA ONAL | H22: =IFERROR(VLOOKUP(F22,'Personel Bilgi'!A:D,3,0),"- - -") -> KURSAD TERCANLI | I22: =IFERROR(VLOOKUP(F22,'Personel Bilgi'!A:D,4,0),"- - -") -> ERZURUM | J22: =IFERROR(VLOOKUP(F22,'Personel Bilgi'!A:E,5,0),"- - -") -> MÜŞTERİ TEMSİLCİSİ | K22: GENEL TALEPLER | L22: DAVRANIŞ | M22: MÜŞTERİNİN YÜZÜNE TELEFON KAPATMA | N22: 45997 | O22: 45999 | P22: GEÇERSİZ ŞİKAYET | Q22: - | R22: HALİDE PALAVAR | S22: YAPILMADI | T22: HAYIR | U22: - | V22: ARALIK | W22: 500131 | X22: =IFERROR(VLOOKUP(W22,'Personel Bilgi'!A:B,2,0),"---") -> SIBEL ATES | Y22: =IFERROR(VLOOKUP(W22,'Personel Bilgi'!A:C,3,0),"---") -> TURGUT AKDAG | Z22: HAYIR | AA22: HATASIZ ÇAĞRI | AB22: GENEL TALEPLER | AC22: DAVRANIŞ | AD22: MÜŞTERİNİN YÜZÜNE TELEFON KAPATMA
A23: ÇAĞRI MERKEZİ | B23: * 29588671274849 | C23: 5437876246 | D23: BEDAŞ | E23: =IFERROR(VLOOKUP(D23,Tanımlar!C:D,2,0),"- - -") -> DAĞITIM | F23: 500186 | G23: =IFERROR(VLOOKUP(F23,'Personel Bilgi'!A:B,2,0),"- - - ") -> MUHAMMET TALHA ATAY | H23: =IFERROR(VLOOKUP(F23,'Personel Bilgi'!A:D,3,0),"- - -") -> TURGUT AKDAG | I23: =IFERROR(VLOOKUP(F23,'Personel Bilgi'!A:D,4,0),"- - -") -> ERZURUM | J23: =IFERROR(VLOOKUP(F23,'Personel Bilgi'!A:E,5,0),"- - -") -> MÜŞTERİ TEMSİLCİSİ | K23: ARIZA | L23: DAVRANIŞ | M23: MÜŞTERİNİN YÜZÜNE TELEFON KAPATMA | N23: 45997 | O23: 45999 | P23: GEÇERSİZ ŞİKAYET | Q23: - | R23: HALİDE PALAVAR | S23: YAPILMADI | T23: HAYIR | U23: - | V23: ARALIK | W23: 500131 | X23: =IFERROR(VLOOKUP(W23,'Personel Bilgi'!A:B,2,0),"---") -> SIBEL ATES | Y23: =IFERROR(VLOOKUP(W23,'Personel Bilgi'!A:C,3,0),"---") -> TURGUT AKDAG | Z23: HAYIR | AA23: HATASIZ ÇAĞRI | AB23: ARIZA | AC23: DAVRANIŞ | AD23: MÜŞTERİNİN YÜZÜNE TELEFON KAPATMA
A24: ÇAĞRI MERKEZİ | B24: *80569015951776 | C24: 5451348223 | D24: BEDAŞ | E24: =IFERROR(VLOOKUP(D24,Tanımlar!C:D,2,0),"- - -") -> DAĞITIM | F24: 600611 | G24: =IFERROR(VLOOKUP(F24,'Personel Bilgi'!A:B,2,0),"- - - ") -> ZEYNEP KOC | H24: =IFERROR(VLOOKUP(F24,'Personel Bilgi'!A:D,3,0),"- - -") -> FERHAT DEMIR | I24: =IFERROR(VLOOKUP(F24,'Personel Bilgi'!A:D,4,0),"- - -") -> ANKARA | J24: =IFERROR(VLOOKUP(F24,'Personel Bilgi'!A:E,5,0),"- - -") -> MÜŞTERİ TEMSİLCİSİ | K24: AYDINLATMA | L24: DAVRANIŞ | M24: TAVIR, TARZ YAPMAK, SES YÜKSELTMEK VB. | N24: 45997 | O24: 45999 | P24: GEÇERSİZ ŞİKAYET | Q24: - | R24: HALİDE PALAVAR | S24: YAPILDI | T24: HAYIR | U24: 90 | V24: ARALIK | W24: 500131 | X24: =IFERROR(VLOOKUP(W24,'Personel Bilgi'!A:B,2,0),"---") -> SIBEL ATES | Y24: =IFERROR(VLOOKUP(W24,'Personel Bilgi'!A:C,3,0),"---") -> TURGUT AKDAG | Z24: HAYIR | AA24: HATASIZ ÇAĞRI | AB24: AYDINLATMA | AC24: DAVRANIŞ | AD24: TAVIR, TARZ YAPMAK, SES YÜKSELTMEK VB.
A25: ÇAĞRI MERKEZİ | B25: *68159114921115 | C25: 5323228156 | D25: BEDAŞ | E25: =IFERROR(VLOOKUP(D25,Tanımlar!C:D,2,0),"- - -") -> DAĞITIM | F25: 500071 | G25: =IFERROR(VLOOKUP(F25,'Personel Bilgi'!A:B,2,0),"- - - ") -> IREM GOKÇE KATRANLI | H25: =IFERROR(VLOOKUP(F25,'Personel Bilgi'!A:D,3,0),"- - -") -> SALTUK BUGRAHAN TAYMUS | I25: =IFERROR(VLOOKUP(F25,'Personel Bilgi'!A:D,4,0),"- - -") -> ERZURUM | J25: =IFERROR(VLOOKUP(F25,'Personel Bilgi'!A:E,5,0),"- - -") -> MÜŞTERİ TEMSİLCİSİ | K25: GENEL TALEPLER | L25: DAVRANIŞ | M25: MÜŞTERİNİN YÜZÜNE TELEFON KAPATMA | N25: 45997 | O25: 45999 | P25: GEÇERSİZ ŞİKAYET | Q25: - | R25: HALİDE PALAVAR | S25: YAPILMADI | T25: HAYIR | U25: - | V25: ARALIK | W25: 111232 | X25: =IFERROR(VLOOKUP(W25,'Personel Bilgi'!A:B,2,0),"---") -> HASAN FURKAN ASLAN | Y25: =IFERROR(VLOOKUP(W25,'Personel Bilgi'!A:C,3,0),"---") -> SAFAK TOPTAS | Z25: HAYIR | AA25: HATASIZ ÇAĞRI | AB25: GENEL TALEPLER | AC25: DAVRANIŞ | AD25: MÜŞTERİNİN YÜZÜNE TELEFON KAPATMA
A26: ÇAĞRI MERKEZİ | B26: *18106198896754 | C26: 5053843964 | D26: BEDAŞ | E26: =IFERROR(VLOOKUP(D26,Tanımlar!C:D,2,0),"- - -") -> DAĞITIM | F26: 500049 | G26: =IFERROR(VLOOKUP(F26,'Personel Bilgi'!A:B,2,0),"- - - ") -> FERHAT ATICI | H26: =IFERROR(VLOOKUP(F26,'Personel Bilgi'!A:D,3,0),"- - -") -> MEHMET ALI SAVAN | I26: =IFERROR(VLOOKUP(F26,'Personel Bilgi'!A:D,4,0),"- - -") -> ERZURUM | J26: =IFERROR(VLOOKUP(F26,'Personel Bilgi'!A:E,5,0),"- - -") -> MÜŞTERİ TEMSİLCİSİ | K26: AYDINLATMA | L26: TEŞEKKÜR | M26: MÜŞTERİ TEMSİLCİSİNE TEŞEKKÜR | N26: 45998 | O26: 45999 | P26: GEÇERSİZ TEŞEKKÜR | Q26: - | R26: HALİDE PALAVAR | S26: YAPILDI | T26: HAYIR | U26: 83 | V26: ARALIK | W26: 500049 | X26: =IFERROR(VLOOKUP(W26,'Personel Bilgi'!A:B,2,0),"---") -> FERHAT ATICI | Y26: =IFERROR(VLOOKUP(W26,'Personel Bilgi'!A:C,3,0),"---") -> MEHMET ALI SAVAN | Z26: EVET | AA26: HATALI / EKSİK BİLGİ VERME | AB26: AYDINLATMA | AC26: TEŞEKKÜR | AD26: MÜŞTERİ TEMSİLCİSİNE TEŞEKKÜR
A27: ÇAĞRI MERKEZİ | B27: *34361350757979 | C27: 5459063289 | D27: BEDAŞ | E27: =IFERROR(VLOOKUP(D27,Tanımlar!C:D,2,0),"- - -") -> DAĞITIM | F27: 111241 | G27: =IFERROR(VLOOKUP(F27,'Personel Bilgi'!A:B,2,0),"- - - ") -> GURKAN KILDIS | H27: =IFERROR(VLOOKUP(F27,'Personel Bilgi'!A:D,3,0),"- - -") -> YAPRAK KARAKOC | I27: =IFERROR(VLOOKUP(F27,'Personel Bilgi'!A:D,4,0),"- - -") -> KARS | J27: =IFERROR(VLOOKUP(F27,'Personel Bilgi'!A:E,5,0),"- - -") -> MÜŞTERİ TEMSİLCİSİ | K27: GENEL TALEPLER | L27: DAVRANIŞ | M27: MÜŞTERİNİN YÜZÜNE TELEFON KAPATMA | N27: 45998 | O27: 45999 | P27: GEÇERSİZ ŞİKAYET | Q27: - | R27: HALİDE PALAVAR | S27: YAPILMADI | T27: HAYIR | U27: - | V27: ARALIK | W27: 111243 | X27: =IFERROR(VLOOKUP(W27,'Personel Bilgi'!A:B,2,0),"---") -> FATMA SENA SEFEROGLU | Y27: =IFERROR(VLOOKUP(W27,'Personel Bilgi'!A:C,3,0),"---") -> SAFAK TOPTAS | Z27: HAYIR | AA27: HATASIZ ÇAĞRI | AB27: GENEL TALEPLER | AC27: DAVRANIŞ | AD27: MÜŞTERİNİN YÜZÜNE TELEFON KAPATMA
A28: ÇAĞRI MERKEZİ | B28: *60636296490951 | C28: 5348736898 | D28: BEDAŞ | E28: =IFERROR(VLOOKUP(D28,Tanımlar!C:D,2,0),"- - -") -> DAĞITIM | F28: 110742 | G28: =IFERROR(VLOOKUP(F28,'Personel Bilgi'!A:B,2,0),"- - - ") -> HANDE KOC | H28: =IFERROR(VLOOKUP(F28,'Personel Bilgi'!A:D,3,0),"- - -") -> YAPRAK KARAKOC | I28: =IFERROR(VLOOKUP(F28,'Personel Bilgi'!A:D,4,0),"- - -") -> KARS | J28: =IFERROR(VLOOKUP(F28,'Personel Bilgi'!A:E,5,0),"- - -") -> MÜŞTERİ TEMSİLCİSİ | K28: ARIZA | L28: ÜRÜN | M28: HATALI / EKSİK KESİNTİ SÜREÇLERİ BİLGİLENDİRMESİ | N28: 45998 | O28: 45999 | P28: GEÇERSİZ ŞİKAYET | Q28: - | R28: HALİDE PALAVAR | S28: YAPILDI | T28: EVET | U28: 0 | V28: ARALIK | W28: 500048 | X28: =IFERROR(VLOOKUP(W28,'Personel Bilgi'!A:B,2,0),"---") -> FATMA NUR TASBASI | Y28: =IFERROR(VLOOKUP(W28,'Personel Bilgi'!A:C,3,0),"---") -> MEHMET ALI SAVAN | Z28: HAYIR | AA28: HATASIZ ÇAĞRI | AB28: ARIZA | AC28: ÜRÜN | AD28: HATALI / EKSİK KESİNTİ SÜREÇLERİ BİLGİLENDİRMESİ
A29: ÇAĞRI MERKEZİ | B29: * 32179803957511 | C29: 5331525050 | D29: BEDAŞ | E29: =IFERROR(VLOOKUP(D29,Tanımlar!C:D,2,0),"- - -") -> DAĞITIM | F29: 600617 | G29: =IFERROR(VLOOKUP(F29,'Personel Bilgi'!A:B,2,0),"- - - ") -> ELMAS AKSOY | H29: =IFERROR(VLOOKUP(F29,'Personel Bilgi'!A:D,3,0),"- - -") -> İNAN UMUT ÖRNEK | I29: =IFERROR(VLOOKUP(F29,'Personel Bilgi'!A:D,4,0),"- - -") -> ANKARA | J29: =IFERROR(VLOOKUP(F29,'Personel Bilgi'!A:E,5,0),"- - -") -> MÜŞTERİ TEMSİLCİSİ | K29: ARIZA | L29: ÜRÜN | M29: HATALI / EKSİK KESİNTİ SÜREÇLERİ BİLGİLENDİRMESİ | N29: 45998 | O29: 45999 | P29: GEÇERSİZ ŞİKAYET | Q29: - | R29: HALİDE PALAVAR | S29: YAPILDI | T29: HAYIR | U29: 100 | V29: ARALIK | W29: 111123 | X29: =IFERROR(VLOOKUP(W29,'Personel Bilgi'!A:B,2,0),"---") -> OZNUR KIRTAY | Y29: =IFERROR(VLOOKUP(W29,'Personel Bilgi'!A:C,3,0),"---") -> SEDA SEBU | Z29: HAYIR | AA29: HATASIZ ÇAĞRI | AB29: ARIZA | AC29: ÜRÜN | AD29: HATALI / EKSİK KESİNTİ SÜREÇLERİ BİLGİLENDİRMESİ
A30: ÇAĞRI MERKEZİ | B30: * 32179803957511 | C30: 5331525050 | D30: BEDAŞ | E30: =IFERROR(VLOOKUP(D30,Tanımlar!C:D,2,0),"- - -") -> DAĞITIM | F30: 600524 | G30: =IFERROR(VLOOKUP(F30,'Personel Bilgi'!A:B,2,0),"- - - ") -> MELIKE NAZIK SAHIN | H30: =IFERROR(VLOOKUP(F30,'Personel Bilgi'!A:D,3,0),"- - -") -> FERHAT DEMIR | I30: =IFERROR(VLOOKUP(F30,'Personel Bilgi'!A:D,4,0),"- - -") -> ANKARA | J30: =IFERROR(VLOOKUP(F30,'Personel Bilgi'!A:E,5,0),"- - -") -> TAKIM LİDERİ | K30: ARIZA | L30: ÜRÜN | M30: HATALI / EKSİK KESİNTİ SÜREÇLERİ BİLGİLENDİRMESİ | N30: 45998 | O30: 45999 | P30: SÖZLÜ UYARI YAPILDI | Q30: - | R30: HALİDE PALAVAR | S30: YAPILDI | T30: EVET | U30: 0 | V30: ARALIK | W30: 111123 | X30: =IFERROR(VLOOKUP(W30,'Personel Bilgi'!A:B,2,0),"---") -> OZNUR KIRTAY | Y30: =IFERROR(VLOOKUP(W30,'Personel Bilgi'!A:C,3,0),"---") -> SEDA SEBU | Z30: HAYIR | AA30: HATASIZ ÇAĞRI | AB30: ARIZA | AC30: ÜRÜN | AD30: HATALI / EKSİK KESİNTİ SÜREÇLERİ BİLGİLENDİRMESİ
A31: ÇAĞRI MERKEZİ | B31: * 32179803957511 | C31: 5331525050 | D31: BEDAŞ | E31: =IFERROR(VLOOKUP(D31,Tanımlar!C:D,2,0),"- - -") -> DAĞITIM | F31: 210169 | G31: =IFERROR(VLOOKUP(F31,'Personel Bilgi'!A:B,2,0),"- - - ") -> NAIM UREYIL | H31: =IFERROR(VLOOKUP(F31,'Personel Bilgi'!A:D,3,0),"- - -") -> SAFAK TOPTAS | I31: =IFERROR(VLOOKUP(F31,'Personel Bilgi'!A:D,4,0),"- - -") -> KARS | J31: =IFERROR(VLOOKUP(F31,'Personel Bilgi'!A:E,5,0),"- - -") -> MÜŞTERİ TEMSİLCİSİ | K31: ARIZA | L31: ÜRÜN | M31: HATALI / EKSİK KESİNTİ SÜREÇLERİ BİLGİLENDİRMESİ | N31: 45998 | O31: 45999 | P31: GEÇERSİZ ŞİKAYET | Q31: - | R31: HALİDE PALAVAR | S31: YAPILDI | T31: EVET | U31: 0 | V31: ARALIK | W31: 111123 | X31: =IFERROR(VLOOKUP(W31,'Personel Bilgi'!A:B,2,0),"---") -> OZNUR KIRTAY | Y31: =IFERROR(VLOOKUP(W31,'Personel Bilgi'!A:C,3,0),"---") -> SEDA SEBU | Z31: HAYIR | AA31: HATASIZ ÇAĞRI | AB31: ARIZA | AC31: ÜRÜN | AD31: HATALI / EKSİK KESİNTİ SÜREÇLERİ BİLGİLENDİRMESİ
A32: ÇAĞRI MERKEZİ | B32: * 32179803957511 | C32: 5331525050 | D32: BEDAŞ | E32: =IFERROR(VLOOKUP(D32,Tanımlar!C:D,2,0),"- - -") -> DAĞITIM | F32: 210373 | G32: =IFERROR(VLOOKUP(F32,'Personel Bilgi'!A:B,2,0),"- - - ") -> MEHTAP KIRTAY | H32: =IFERROR(VLOOKUP(F32,'Personel Bilgi'!A:D,3,0),"- - -") -> MUSTAFA OZAYAG | I32: =IFERROR(VLOOKUP(F32,'Personel Bilgi'!A:D,4,0),"- - -") -> KARS | J32: =IFERROR(VLOOKUP(F32,'Personel Bilgi'!A:E,5,0),"- - -") -> MÜŞTERİ TEMSİLCİSİ | K32: ARIZA | L32: ÜRÜN | M32: HATALI / EKSİK KESİNTİ SÜREÇLERİ BİLGİLENDİRMESİ | N32: 45998 | O32: 45999 | P32: GEÇERSİZ ŞİKAYET | Q32: - | R32: HALİDE PALAVAR | S32: YAPILDI | T32: HAYIR | U32: 100 | V32: ARALIK | W32: 111123 | X32: =IFERROR(VLOOKUP(W32,'Personel Bilgi'!A:B,2,0),"---") -> OZNUR KIRTAY | Y32: =IFERROR(VLOOKUP(W32,'Personel Bilgi'!A:C,3,0),"---") -> SEDA SEBU | Z32: HAYIR | AA32: HATASIZ ÇAĞRI | AB32: ARIZA | AC32: ÜRÜN | AD32: HATALI / EKSİK KESİNTİ SÜREÇLERİ BİLGİLENDİRMESİ
A33: ÇAĞRI MERKEZİ | B33: *82245115182129 | C33: 5466354881 | D33: BEDAŞ | E33: =IFERROR(VLOOKUP(D33,Tanımlar!C:D,2,0),"- - -") -> DAĞITIM | F33: 110852 | G33: =IFERROR(VLOOKUP(F33,'Personel Bilgi'!A:B,2,0),"- - - ") -> UGURCAN ALTUNTERIM | H33: =IFERROR(VLOOKUP(F33,'Personel Bilgi'!A:D,3,0),"- - -") -> SEDA SEBU | I33: =IFERROR(VLOOKUP(F33,'Personel Bilgi'!A:D,4,0),"- - -") -> KARS | J33: =IFERROR(VLOOKUP(F33,'Personel Bilgi'!A:E,5,0),"- - -") -> MÜŞTERİ TEMSİLCİSİ | K33: ARIZA | L33: ÜRÜN | M33: HATALI / EKSİK KESİNTİ SÜREÇLERİ BİLGİLENDİRMESİ | N33: 45998 | O33: 45999 | P33: SÖZLÜ UYARI YAPILDI | Q33: - | R33: HALİDE PALAVAR | S33: YAPILDI | T33: HAYIR | U33: 75 | V33: ARALIK | W33: 600468 | X33: =IFERROR(VLOOKUP(W33,'Personel Bilgi'!A:B,2,0),"---") -> FATMA NUR SAHIN | Y33: =IFERROR(VLOOKUP(W33,'Personel Bilgi'!A:C,3,0),"---") -> İNAN UMUT ÖRNEK | Z33: HAYIR | AA33: HATASIZ ÇAĞRI | AB33: ARIZA | AC33: ÜRÜN | AD33: HATALI / EKSİK KESİNTİ SÜREÇLERİ BİLGİLENDİRMESİ
A34: ÇAĞRI MERKEZİ | B34: *82245115182129 | C34: 5466354881 | D34: BEDAŞ | E34: =IFERROR(VLOOKUP(D34,Tanımlar!C:D,2,0),"- - -") -> DAĞITIM | F34: 110484 | G34: =IFERROR(VLOOKUP(F34,'Personel Bilgi'!A:B,2,0),"- - - ") -> BIRAN ZAKKUM IVAK | H34: =IFERROR(VLOOKUP(F34,'Personel Bilgi'!A:D,3,0),"- - -") -> YAREN OZAYAG | I34: =IFERROR(VLOOKUP(F34,'Personel Bilgi'!A:D,4,0),"- - -") -> KARS | J34: =IFERROR(VLOOKUP(F34,'Personel Bilgi'!A:E,5,0),"- - -") -> MÜŞTERİ TEMSİLCİSİ | K34: ARIZA | L34: ÜRÜN | M34: HATALI / EKSİK KESİNTİ SÜREÇLERİ BİLGİLENDİRMESİ | N34: 45998 | O34: 45999 | P34: SÖZLÜ UYARI YAPILDI | Q34: - | R34: HALİDE PALAVAR | S34: YAPILDI | T34: HAYIR | U34: 75 | V34: ARALIK | W34: 110484 | X34: =IFERROR(VLOOKUP(W34,'Personel Bilgi'!A:B,2,0),"---") -> BIRAN ZAKKUM IVAK | Y34: =IFERROR(VLOOKUP(W34,'Personel Bilgi'!A:C,3,0),"---") -> YAREN OZAYAG | Z34: EVET | AA34: HATALI / EKSİK BİLGİ VERME | AB34: ARIZA | AC34: ÜRÜN | AD34: HATALI / EKSİK KESİNTİ SÜREÇLERİ BİLGİLENDİRMESİ
A35: ÇAĞRI MERKEZİ | B35: * 10587420598190 | C35: 5437723109 | D35: ÇEDAŞ | E35: =IFERROR(VLOOKUP(D35,Tanımlar!C:D,2,0),"- - -") -> DAĞITIM | F35: 110539 | G35: =IFERROR(VLOOKUP(F35,'Personel Bilgi'!A:B,2,0),"- - - ") -> TAYLAN OZGUR DURMUS | H35: =IFERROR(VLOOKUP(F35,'Personel Bilgi'!A:D,3,0),"- - -") -> YAREN OZAYAG | I35: =IFERROR(VLOOKUP(F35,'Personel Bilgi'!A:D,4,0),"- - -") -> KARS | J35: =IFERROR(VLOOKUP(F35,'Personel Bilgi'!A:E,5,0),"- - -") -> MÜŞTERİ TEMSİLCİSİ | K35: ARIZA | L35: DAVRANIŞ | M35: TAVIR, TARZ YAPMAK, SES YÜKSELTMEK VB. | N35: 45996 | O35: 46000 | P35: YAZILI UYARI YAPILDI | Q35: - | R35: HALİDE PALAVAR | S35: YAPILDI | T35: EVET | U35: 0 | V35: ARALIK | W35: 111239 | X35: =IFERROR(VLOOKUP(W35,'Personel Bilgi'!A:B,2,0),"---") -> HIRANUR KALKAN | Y35: =IFERROR(VLOOKUP(W35,'Personel Bilgi'!A:C,3,0),"---") -> SEVCAN BULUT | Z35: HAYIR | AA35: HATASIZ ÇAĞRI | AB35: ARIZA | AC35: DAVRANIŞ | AD35: TAVIR, TARZ YAPMAK, SES YÜKSELTMEK VB.
A36: ÇAĞRI MERKEZİ | B36: * 10587420598190 | C36: 5437723109 | D36: ÇEDAŞ | E36: =IFERROR(VLOOKUP(D36,Tanımlar!C:D,2,0),"- - -") -> DAĞITIM | F36: 111252 | G36: =IFERROR(VLOOKUP(F36,'Personel Bilgi'!A:B,2,0),"- - - ") -> BARAN KOYUNCU | H36: =IFERROR(VLOOKUP(F36,'Personel Bilgi'!A:D,3,0),"- - -") -> YAREN OZAYAG | I36: =IFERROR(VLOOKUP(F36,'Personel Bilgi'!A:D,4,0),"- - -") -> KARS | J36: =IFERROR(VLOOKUP(F36,'Personel Bilgi'!A:E,5,0),"- - -") -> MÜŞTERİ TEMSİLCİSİ | K36: ARIZA | L36: DAVRANIŞ | M36: TAVIR, TARZ YAPMAK, SES YÜKSELTMEK VB. | N36: 45996 | O36: 46000 | P36: SÖZLÜ UYARI YAPILDI | Q36: - | R36: HALİDE PALAVAR | S36: YAPILDI | T36: HAYIR | U36: 41 | V36: ARALIK | W36: 111239 | X36: =IFERROR(VLOOKUP(W36,'Personel Bilgi'!A:B,2,0),"---") -> HIRANUR KALKAN | Y36: =IFERROR(VLOOKUP(W36,'Personel Bilgi'!A:C,3,0),"---") -> SEVCAN BULUT | Z36: HAYIR | AA36: HATASIZ ÇAĞRI | AB36: ARIZA | AC36: DAVRANIŞ | AD36: TAVIR, TARZ YAPMAK, SES YÜKSELTMEK VB.
A37: ÇAĞRI MERKEZİ | B37: * 98692030062890 | C37: 5312590105 | D37: ÇEDAŞ | E37: =IFERROR(VLOOKUP(D37,Tanımlar!C:D,2,0),"- - -") -> DAĞITIM | F37: 111182 | G37: =IFERROR(VLOOKUP(F37,'Personel Bilgi'!A:B,2,0),"- - - ") -> DIDEM KENCU | H37: =IFERROR(VLOOKUP(F37,'Personel Bilgi'!A:D,3,0),"- - -") -> SEVCAN BULUT | I37: =IFERROR(VLOOKUP(F37,'Personel Bilgi'!A:D,4,0),"- - -") -> KARS | J37: =IFERROR(VLOOKUP(F37,'Personel Bilgi'!A:E,5,0),"- - -") -> MÜŞTERİ TEMSİLCİSİ | K37: ARIZA | L37: ÜRÜN | M37: HATALI / EKSİK KESİNTİ SÜREÇLERİ BİLGİLENDİRMESİ | N37: 45996 | O37: 46000 | P37: GEÇERSİZ ŞİKAYET | Q37: - | R37: HALİDE PALAVAR | S37: YAPILDI | T37: EVET | U37: 0 | V37: ARALIK | W37: 111239 | X37: =IFERROR(VLOOKUP(W37,'Personel Bilgi'!A:B,2,0),"---") -> HIRANUR KALKAN | Y37: =IFERROR(VLOOKUP(W37,'Personel Bilgi'!A:C,3,0),"---") -> SEVCAN BULUT | Z37: HAYIR | AA37: HATASIZ ÇAĞRI | AB37: ARIZA | AC37: ÜRÜN | AD37: HATALI / EKSİK KESİNTİ SÜREÇLERİ BİLGİLENDİRMESİ
A38: ÇAĞRI MERKEZİ | B38: *83686419794734 | C38: 5522316019 | D38: ÇEDAŞ | E38: =IFERROR(VLOOKUP(D38,Tanımlar!C:D,2,0),"- - -") -> DAĞITIM | F38: 110486 | G38: =IFERROR(VLOOKUP(F38,'Personel Bilgi'!A:B,2,0),"- - - ") -> BUKET CANSU BEKTEMUR | H38: =IFERROR(VLOOKUP(F38,'Personel Bilgi'!A:D,3,0),"- - -") -> SAFAK TOPTAS | I38: =IFERROR(VLOOKUP(F38,'Personel Bilgi'!A:D,4,0),"- - -") -> KARS | J38: =IFERROR(VLOOKUP(F38,'Personel Bilgi'!A:E,5,0),"- - -") -> MÜŞTERİ TEMSİLCİSİ | K38: ARIZA | L38: TEŞEKKÜR | M38: MÜŞTERİ TEMSİLCİSİNE TEŞEKKÜR | N38: 45998 | O38: 46000 | P38: GEÇERLİ TEŞEKKÜR | Q38: - | R38: HALİDE PALAVAR | S38: YAPILDI | T38: HAYIR | U38: 100 | V38: ARALIK | W38: 110486 | X38: =IFERROR(VLOOKUP(W38,'Personel Bilgi'!A:B,2,0),"---") -> BUKET CANSU BEKTEMUR | Y38: =IFERROR(VLOOKUP(W38,'Personel Bilgi'!A:C,3,0),"---") -> SAFAK TOPTAS | Z38: HAYIR | AA38: HATASIZ ÇAĞRI | AB38: ARIZA | AC38: TEŞEKKÜR | AD38: MÜŞTERİ TEMSİLCİSİNE TEŞEKKÜR
A39: ÇAĞRI MERKEZİ | B39: *34297522472992 | C39: 5456722250 | D39: BEDAŞ | E39: =IFERROR(VLOOKUP(D39,Tanımlar!C:D,2,0),"- - -") -> DAĞITIM | F39: 500049 | G39: =IFERROR(VLOOKUP(F39,'Personel Bilgi'!A:B,2,0),"- - - ") -> FERHAT ATICI | H39: =IFERROR(VLOOKUP(F39,'Personel Bilgi'!A:D,3,0),"- - -") -> MEHMET ALI SAVAN | I39: =IFERROR(VLOOKUP(F39,'Personel Bilgi'!A:D,4,0),"- - -") -> ERZURUM | J39: =IFERROR(VLOOKUP(F39,'Personel Bilgi'!A:E,5,0),"- - -") -> MÜŞTERİ TEMSİLCİSİ | K39: GENEL TALEPLER | L39: DAVRANIŞ | M39: MÜŞTERİNİN YÜZÜNE TELEFON KAPATMA | N39: 45999 | O39: 46000 | P39: GEÇERSİZ ŞİKAYET | Q39: - | R39: HALİDE PALAVAR | S39: YAPILMADI | T39: HAYIR | U39: - | V39: ARALIK | W39: 600593 | X39: =IFERROR(VLOOKUP(W39,'Personel Bilgi'!A:B,2,0),"---") -> FATIH MERCAN | Y39: =IFERROR(VLOOKUP(W39,'Personel Bilgi'!A:C,3,0),"---") -> İNAN UMUT ÖRNEK | Z39: HAYIR | AA39: HATASIZ ÇAĞRI | AB39: GENEL TALEPLER | AC39: DAVRANIŞ | AD39: MÜŞTERİNİN YÜZÜNE TELEFON KAPATMA
A40: ÇAĞRI MERKEZİ | B40: * 56198053727377 | C40: 5334803838 | D40: AEDAŞ | E40: =IFERROR(VLOOKUP(D40,Tanımlar!C:D,2,0),"- - -") -> DAĞITIM | F40: 111241 | G40: =IFERROR(VLOOKUP(F40,'Personel Bilgi'!A:B,2,0),"- - - ") -> GURKAN KILDIS | H40: =IFERROR(VLOOKUP(F40,'Personel Bilgi'!A:D,3,0),"- - -") -> YAPRAK KARAKOC | I40: =IFERROR(VLOOKUP(F40,'Personel Bilgi'!A:D,4,0),"- - -") -> KARS | J40: =IFERROR(VLOOKUP(F40,'Personel Bilgi'!A:E,5,0),"- - -") -> MÜŞTERİ TEMSİLCİSİ | K40: ARIZA | L40: TEŞEKKÜR | M40: MÜŞTERİ TEMSİLCİSİNE TEŞEKKÜR | N40: 45996 | O40: 46000 | P40: GEÇERLİ TEŞEKKÜR | Q40: - | R40: HALİDE PALAVAR | S40: YAPILDI | T40: HAYIR | U40: 90 | V40: ARALIK | W40: 500109 | X40: =IFERROR(VLOOKUP(W40,'Personel Bilgi'!A:B,2,0),"---") -> MUHAMMET EMIN AKSAKAL | Y40: =IFERROR(VLOOKUP(W40,'Personel Bilgi'!A:C,3,0),"---") -> METEHAN EMRE SIRMALI | Z40: HAYIR | AA40: HATASIZ ÇAĞRI | AB40: ARIZA | AC40: TEŞEKKÜR | AD40: MÜŞTERİ TEMSİLCİSİNE TEŞEKKÜR
...

Sheet Tanımlar
A1: Geliş Kanalı | B1: Lokasyon | C1: ŞİRKET | D1: SKILL | E1: Unvan | F1: SÜREÇ | G1: ÜRÜN | H1: DAVRANIŞ | I1: TEŞEKKÜR | J1: Çağrı Konusu | K1: Yapılacak İş Sonucu | L1: Kalite Yetkilisi | M1: Kalite Değerlendirmesi | N1: Mail İletildi Mi? | O1: Kayıt Oluşturan MT Hatalı Mı? | P1: Hata Sebebi Olan Durum Nedir? | Q1: Fraud (Tele Satış)
A2: ÇAĞRI MERKEZİ | B2: KARS | C2: AEDAŞ | D2: DAĞITIM | E2: TAKIM LİDERİ | F2: HATALI MÜHİM/MOD/ÇAĞRI MERKEZİ VB. YÖNLENDİRME | G2: HATALI / EKSİK BORÇ BİLGİLENDİRMESİ | H2: TAVIR, TARZ YAPMAK, SES YÜKSELTMEK VB. | I2: MÜŞTERİ TEMSİLCİSİNE TEŞEKKÜR | J2: ARIZA | K2: ÇAĞRI MERKEZİNE TEŞEKKÜR | L2: HABIBE KARABIYIK | M2: YAPILDI | N2: EVET | O2: EVET | P2: HATASIZ ÇAĞRI | Q2: VAR
A3: EPDK | B3: ERZURUM | C3: AEPSAŞ | D3: PERAKENDE | E3: M.TEMSİLCİSİ | F3: YETKİLİYE AKTARMAMA | G3: HATALI / EKSİK ABONELİK BİLGİLENDİRMESİ | H3: STANDARDA UYGUN OLMAYAN ÇAĞRI SONLANDIRMA | I3: TAKIM LİDERİNE TEŞEKKÜR | J3: AYDINLATMA | K3: GEÇERLİ TEŞEKKÜR | L3: FATİH BAŞTUĞ | M3: YAPILMADI | N3: HAYIR | O3: HAYIR | P3: ŞİKAYETE YÖNLENDİRME | Q3: YOK
A4: CİMER | B4: ANKARA | C4: BEDAŞ | D4: DAĞITIM | E4: UZM.M.TEMSİLCİSİ | F4: ŞİKAYET/TEŞEKKÜR KAYDI OLUŞTURMAMA | G4: HATALI / EKSİK İKİLİ ANLAŞMA SÜREÇLERİ BİLGİLENDİRMESİ | H4: MÜŞTERİNİN YÜZÜNE TELEFON KAPATMA | I4: ÇAĞRI MERKEZİNE GENEL OLARAK TEŞEKKÜR | J4: BAĞLANTI ŞEBEKE | K4: GEÇERSİZ ŞİKAYET | L4: MÜNEVVER YILMAZ | P4: HATALI / EKSİK BİLGİ VERME
A5: ŞİRKET İÇ BİRİM | C5: BEPSAŞ | D5: PERAKENDE | F5: HATALI ABONELİK ÜZERİNDEN İŞLEM YAPILMASI | G5: HATALI / EKSİK UK SÜRECİ UYGULANMASI | H5: GÜLMEK, ESNEMEK, BESLENMEK VB. UYGUN OLMAYAN DAVRANIŞ | J5: BİLGİ EDİNME | K5: GEÇERSİZ TEŞEKKÜR | L5: SEYMANUR CEVIK | P5: İKNAYA GİTMEME
C6: ÇEDAŞ | D6: DAĞITIM | F6: HATALI KATEGORİ ÜZERİNDEN KAYIT ALMA | G6: HATALI / EKSİK SKTT SÜRECİ BİLGİLENDİRMESİ | H6: MÜŞTERİYE HİZMET VERMEDEN (5,10,30 SN VB.) ÇAĞRIYI KAPATMAK | J6: İŞLETME TALEPLERİ | K6: ÖZÜR | L6: HALİDE PALAVAR
C7: ÇEPSAŞ | D7: PERAKENDE | F7: LOG KAYDININ OLMAMASI | G7: HATALI / EKSİK DİJİTAL FATURA SÜRECİ UYGULANMASI | J7: KAÇAK | K7: SÖZLÜ UYARI YARILDI | L7: ÖZLEM BAŞÇAVUŞOĞULLARI
F8: 3. ŞAHIS İLE BİLGİ PAYLAŞILMASI | G8: HATALI / EKSİK İYS SÜRECİ UYGULANMASI | J8: KAMULAŞTIRMA | K8: YAZILI UYARI YAPILDI | L8: RUKİYE DEMİRKALE
F9: HATALI TEŞEKKÜR KAYDI | G9: HATALI / EKSİK GÜVENCE BEDELİ BİLGİLENDİRMESİ | J9: MÜŞTERİ FEN | K9: UYARILDI | L9: FATİH KARADENİZ
F10: HATALI ŞİKAYET KAYDI | G10: HATALI / EKSİK KAÇAK SÜREÇLERİ BİLGİLENDİRMESİ | J10: MÜŞTERİ HİZMETLERİ | L10: YALIN BASBUG
F11: MÜŞTERİ TALEBİNE YARDIMCI OLMAMASI | G11: HATALI / EKSİK AYDINLATMA BİLGİLENDİRMESİ | J11: OSOS İŞLEMLERİ | L11: KADER ERGUN
G12: HATALI / EKSİK SAYAÇ SÜREÇLERİ BİLGİLENDİRMESİ | J12: SAYAÇ İŞLEMLERİ
G13: HATALI / EKSİK AÇMA KESME SÜREÇLERİ BİLGİLENDİRMESİ | J13: TAHAKKUK
G14: HATALI / EKSİK KESİNTİ SÜREÇLERİ BİLGİLENDİRMESİ | J14: TAZMİNATLAR
J15: TEKNİK KALİTE
J16: BORÇ ÖDEME İŞLEMLERİ
J17: GENEL TALEPLER
J18: MÜŞTERİ İŞLEMLERİ
J19: FATURA İŞLEMLERİ
J20: YASAL TAKİP BAŞVURULARI
J21: KAMPANYALAR
J22: BİLGİ VERİLDİ
J23: AÇMA KESME
J24: FATURALAMA ŞİKAYETLERİ
J25: SKTT
J26: CK SATIŞ

Sheet Personel Bilgi
A1: LOGİNID | B1: MÜSTERİ TEMSİLCİSİ | C1: TAKIM LİDERİ | D1: LOKASYON | E1: UNVAN | F1: ÇALIŞMA DURUMU
A2: 210372 | B2: YAPRAK AKBABA | C2: AYSU ARSLAN | D2: KARS | E2: MÜŞTERİ TEMSİLCİSİ | F2: AKTİF
A3: 110558 | B3: TANSU CAM | C3: AYSU ARSLAN | D3: KARS | E3: MÜŞTERİ TEMSİLCİSİ | F3: AKTİF
A4: 210043 | B4: SEVAL TOSUN | C4: AYSU ARSLAN | D4: KARS | E4: MÜŞTERİ TEMSİLCİSİ | F4: AKTİF
A5: 210131 | B5: SENEM ERTAS | C5: AYSU ARSLAN | D5: KARS | E5: TAKIM LİDERİ | F5: AKTİF
A6: 210171 | B6: RABIA KAYA | C6: AYSU ARSLAN | D6: KARS | E6: MÜŞTERİ TEMSİLCİSİ | F6: AKTİF
A7: 210138 | B7: PELIN SU ERDAGI | C7: AYSU ARSLAN | D7: KARS | E7: MÜŞTERİ TEMSİLCİSİ | F7: AKTİF
A8: 110466 | B8: NUR ALEYNA BEKISDAMAT | C8: AYSU ARSLAN | D8: KARS | E8: MÜŞTERİ TEMSİLCİSİ | F8: AKTİF
A9: 210034 | B9: MUNRE KAVRAT | C9: AYSU ARSLAN | D9: KARS | E9: MÜŞTERİ TEMSİLCİSİ | F9: AKTİF
A10: 110287 | B10: GURKAN YAGCI | C10: AYSU ARSLAN | D10: KARS | E10: MÜŞTERİ TEMSİLCİSİ | F10: AKTİF
A11: 110286 | B11: GUNES YILMAZ | C11: AYSU ARSLAN | D11: KARS | E11: TAKIM LİDERİ | F11: AKTİF
A12: 210053 | B12: GULHAN GENCLER | C12: AYSU ARSLAN | D12: KARS | E12: MÜŞTERİ TEMSİLCİSİ | F12: AKTİF
A13: 210114 | B13: GUL ZEHRA KIZGIN | C13: AYSU ARSLAN | D13: KARS | E13: MÜŞTERİ TEMSİLCİSİ | F13: AKTİF
... A605: 110463 | B605: MUHAMMET ACAY | C605: SEDA SEBU | D605: KARS | E605: MÜŞTERİ TEMSİLCİSİ | F605: AKTİF
A606: 999999 | B606: GENEL TEŞEKKÜR | C606: GENEL TEŞEKKÜR | D606: GENEL TEŞEKKÜR | E606: GENEL TEŞEKKÜR
A607: 600032 | B607: ASYA DAG | C607: ASYA DAG | D607: ANKARA | E607: TAKIM LİDERİ | F607: AKTİF
A608: 600345 | B608: FERHAT DEMIR | C608: FERHAT DEMIR | D608: ANKARA | E608: TAKIM LİDERİ | F608: AKTİF
A609: 210005 | B609: AYSU ARSLAN | C609: AYSU ARSLAN | D609: KARS | E609: TAKIM LİDERİ | F609: AKTİF
A610: 500025 | B610: METEHAN EMRE SIRMALI | C610: METEHAN EMRE SIRMALI | D610: ERZURUM | E610: TAKIM LIDERI | F610: AKTİF
A611: 888888 | B611: CİMER | C611: CİMER | D611: CİMER | E611: CİMER | F611: AKTİF
A612: 777777 | B612: EPDK | C612: EPDK | D612: EPDK | E612: EPDK | F612: AKTİF
A613: 666666 | B613: İÇ BİRİM | C613: İÇ BİRİM | D613: İÇ BİRİM | E613: İÇ BİRİM | F613: AKTİF
A614: 600878 | B614: ESRA USTAOGLU | C614: AHMET RIDVAN ERDOGMUS | D614: ANKARA | E614: MÜŞTERİ TEMSİLCİSİ | F614: AKTİF
A615: 110303 | B615: YAREN OZAYAG | C615: YAREN OZAYAG | D615: KARS | E615: TAKIM LİDERİ | F615: AKTİF
A616: 210013 | B616: CEYHAN AYRIC | C616: CEYHAN AYRIC | D616: KARS | E616: TAKIM LİDERİ | F616: AKTİF
A617: 110300 | B617: SEVCA BULUT | C617: SEVCA BULUT | D617: KARS | E617: TAKIM LİDERİ | F617: AKTİF
A618: 210007 | B618: YAPRAK KARAKOC | C618: YAPRAK KARAKOC | D618: KARS | E618: TAKIM LİDERİ | F618: AKTİF
A619: 600892 | B619: AHMET CIHAN ERDEM | C619: DILAN OZDEN | D619: ANKARA | E619: MÜŞTERİ TEMSİLCİSİ | F619: AKTİF

Sheet Sayfa2
A3: Say Lokasyon | B3: Sütun Etiketleri
A4: Satır Etiketleri | B4: - - - | C4: DAĞITIM | D4: PERAKENDE | E4: Genel Toplam
A5: SÜREÇ | C5: 74 | D5: 35 | E5: 109
A6: DAVRANIŞ | C6: 41 | D6: 9 | E6: 50
A7: ÜRÜN | C7: 36 | D7: 5 | E7: 41
A8: (boş) | B8: 27 | C8: 1 | D8: 1 | E8: 29
A9: TEŞEKKÜR | C9: 12 | D9: 3 | E9: 15
A10: Genel Toplam | B10: 27 | C10: 164 | D10: 53 | E10: 244
A13: Say Lokasyon | B13: Sütun Etiketleri
A14: Satır Etiketleri | B14: - - - | C14: DAĞITIM | D14: PERAKENDE | E14: Genel Toplam
A15: SÜREÇ | C15: 74 | D15: 35 | E15: 109
A16: MÜŞTERİ TALEBİNE YARDIMCI OLMAMASI | C16: 44 | D16: 20 | E16: 64
A17: MÜŞTERİNİN YÜZÜNE TELEFON KAPATMA | C17: 6 | D17: 7 | E17: 13
A18: HATALI MÜHİM/MOD/ÇAĞRI MERKEZİ VB. YÖNLENDİRME | C18: 7 | D18: 5 | E18: 12
A19: YETKİLİYE AKTARMAMA | C19: 8 | E19: 8
A20: LOG KAYDININ OLMAMASI | C20: 6 | E20: 6
A21: HATALI KATEGORİ ÜZERİNDEN KAYIT ALMA | C21: 3 | E21: 3
A22: HATALI ABONELİK ÜZERİNDEN İŞLEM YAPILMASI | D22: 3 | E22: 3
A23: DAVRANIŞ | C23: 41 | D23: 9 | E23: 50
A24: MÜŞTERİNİN YÜZÜNE TELEFON KAPATMA | C24: 22 | D24: 4 | E24: 26
A25: TAVIR, TARZ YAPMAK, SES YÜKSELTMEK VB. | C25: 11 | D25: 4 | E25: 15
A26: MÜŞTERİNİN İSTEĞİ DIŞINDA ÇAĞRININ SONLANDIRILMASI | C26: 7 | E26: 7
A27: YETERSİZ VERİ | C27: 1 | E27: 1
A28: STANDARDA UYGUN OLMAYAN ÇAĞRI SONLANDIRMA | D28: 1 | E28: 1
A29: ÜRÜN | C29: 36 | D29: 5 | E29: 41
A30: HATALI / EKSİK KESİNTİ SÜREÇLERİ BİLGİLENDİRMESİ | C30: 20 | E30: 20
A31: HATALI / EKSİK KAÇAK SÜREÇLERİ BİLGİLENDİRMESİ | C31: 7 | E31: 7
A32: HATALI / EKSİK SAYAÇ SÜREÇLERİ BİLGİLENDİRMESİ | C32: 6 | E32: 6
A33: HATALI / EKSİK AYDINLATMA BİLGİLENDİRMESİ | C33: 3 | E33: 3
A34: HATALI / EKSİK BORÇ BİLGİLENDİRMESİ | D34: 2 | E34: 2
A35: HATALI / EKSİK İKİLİ ANLAŞMA SÜREÇLERİ BİLGİLENDİRMESİ | D35: 2 | E35: 2
A36: HATALI / EKSİK GÜVENCE BEDELİ BİLGİLENDİRMESİ | D36: 1 | E36: 1
A37: (boş) | B37: 27 | C37: 1 | D37: 1 | E37: 29
A38: (boş) | B38: 27 | C38: 1 | E38: 28
A39: YETERSİZ VERİ | D39: 1 | E39: 1
A40: TEŞEKKÜR | C40: 12 | D40: 3 | E40: 15
A41: MÜŞTERİ TEMSİLCİSİNE TEŞEKKÜR | C41: 10 | D41: 3 | E41: 13
A42: ÇAĞRI MERKEZİNE GENEL OLARAK TEŞEKKÜR | C42: 2 | E42: 2
A43: Genel Toplam | B43: 27 | C43: 164 | D43: 53 | E43: 244

Sheet Sayfa1
B2: GEÇERLİ ŞİKAYET | C2: GEÇERSİZ ŞİKAYET | D2: GEÇERLİ TEŞEKKÜR | E2: GEÇERSİZ TEŞEKKÜR | F2: ÇAĞRI MERKEZİNE TEŞEKKÜR | G2: ÖZÜR
B3: Yazılı Uyarı | C3: İşlem Yok | D3: İşlem Yok | E3: İşlem Yok | F3: İşlem Yok | G3: İşlem Yok
B4: Sözlü Uyarı
B5: Uyarıldı
